Workbook
Name _Helper: Inputs!$B$10
Name AvgPrice: AVERAGE(Data!$D$2:$D$21)
Name BonusAmount: Inputs!$B$10
Name CommissionTable: Inputs!$D$2:$E$5
Name CommRates: Inputs!$E$2:$E$5
Name CommRegions: Inputs!$D$2:$D$5
Name CompanyName: Inputs!$B$7
Name ConstGreeting: "Hello"
Name ConstPi: 3.14159
Name ConstVAT: 0.2
Name DiscountRate: Inputs!$B$3
Name DoubleTarget: Inputs!$B$6*2
Name DynRevenue: Data!$E$2:INDEX(Data!$E:$E,COUNTA(Data!$A:$A))
Name DynUnits: OFFSET(Data!$C$2,0,0,COUNTA(Data!$C:$C)-1,1)
Name EmptyRange: Data!$G$2:$G$5
Name FirstFiveUnits: Data!$C$2:$C$6
Name FirstRegion: Data!$A$2
Name FXRate: Inputs!$B$4
Name GrossWithTax: TotalRevenue*(1+TaxRate)
Name HeaderRow: Data!$1:$1
Name LastFiveUnits: Data!$C$17:$C$21
Name LastRevenue: Data!$E$21
Name LocalBonus: Inputs!$B$10
Name lowercasename: Inputs!$B$8
Name Multiplier: Inputs!$B$9
Name Prices: Data!$D$2:$D$21
Name Products: Data!$B$2:$B$21
Name Q1Months: 'Q1 Sales'!$A$2:$A$4
Name Q1Total: 'Q1 Sales'!$B$5
Name Q1Values: 'Q1 Sales'!$B$2:$B$4
Name Rate.Commission: Inputs!$E$2
Name Regions: Data!$A$2:$A$21
Name Revenue: Data!$E$2:$E$21
Name RevenueAfterTax: SUM(Data!$E$2:$E$21)*(1-Inputs!$B$2)
Name Sales_2024: Data!$E$2:$E$11
Name SalesHeader: Data!$A$1:$E$1
Name SalesTable: Data!$A$2:$E$21
Name SalesTarget: Inputs!$B$6
Name Scope_Test: Data!$C$2
Name Scope_Test: Inputs!$B$9
Name StartDate: Inputs!$B$5
Name TaxRate: Inputs!$B$2
Name This_Is_A_Very_Long_Named_Range_For_Testing: Data!$C$2:$C$21
Name Threshold: Inputs!$B$8
Name TopLeftBlock: Data!$C$2:$D$4
Name TotalRevenue: SUM(Data!$E$2:$E$21)
Name UnionRange: Data!$C$2:$C$4,Data!$C$19:$C$21
Name Units: Data!$C$2:$C$21
Name UnitsColumn: Data!$C:$C

Sheet Tests
A1: IronCalc #1581 – Named Ranges Test
A2: Passed | B2: =COUNTIF(G5:G63,"PASS")&" / "&ROWS(G5:G63) -> 59 / 59
A3: Result uses the named range; Expected uses the equivalent direct cell reference. Status = PASS when they match.
A4: # | B4: Category | C4: Name(s) tested | D4: Formula | E4: Result (via name) | F4: Expected (direct ref) | G4: Status
A5: 1 | B5: Single cell | C5: TaxRate | D5: =TaxRate | E5: =TaxRate -> 0.08 | F5: =Inputs!B2 -> 0.08 | G5: =IFERROR(IF(E5=F5,"PASS","FAIL"),"FAIL") -> PASS
A6: 2 | B6: Single cell | C6: DiscountRate | D6: =DiscountRate | E6: =DiscountRate -> 0.05 | F6: =Inputs!B3 -> 0.05 | G6: =IFERROR(IF(E6=F6,"PASS","FAIL"),"FAIL") -> PASS
A7: 3 | B7: Single cell | C7: FXRate | D7: =FXRate*100 | E7: =FXRate*100 -> 110 | F7: =Inputs!B4*100 -> 110 | G7: =IFERROR(IF(E7=F7,"PASS","FAIL"),"FAIL") -> PASS
A8: 4 | B8: Single cell (date) | C8: StartDate | D8: =StartDate+30 | E8: =StartDate+30 -> 46053 | F8: =Inputs!B5+30 -> 46053 | G8: =IFERROR(IF(E8=F8,"PASS","FAIL"),"FAIL") -> PASS
A9: 5 | B9: Single cell | C9: SalesTarget | D9: =SalesTarget | E9: =SalesTarget -> 5000 | F9: =Inputs!B6 -> 5000 | G9: =IFERROR(IF(E9=F9,"PASS","FAIL"),"FAIL") -> PASS
A10: 6 | B10: Single cell (text) | C10: CompanyName | D10: =CompanyName | E10: =CompanyName -> Acme Corp | F10: =Inputs!B7 -> Acme Corp | G10: =IFERROR(IF(E10=F10,"PASS","FAIL"),"FAIL") -> PASS
A11: 7 | B11: Single cell | C11: Threshold | D11: =Threshold | E11: =Threshold -> 50 | F11: =Inputs!B8 -> 50 | G11: =IFERROR(IF(E11=F11,"PASS","FAIL"),"FAIL") -> PASS
A12: 8 | B12: Single cell | C12: Multiplier, BonusAmount | D12: =Multiplier*BonusAmount | E12: =Multiplier*BonusAmount -> 750 | F12: =Inputs!B9*Inputs!B10 -> 750 | G12: =IFERROR(IF(E12=F12,"PASS","FAIL"),"FAIL") -> PASS
A13: 9 | B13: Single cell | C13: FirstRegion | D13: =FirstRegion | E13: =FirstRegion -> North | F13: =Data!A2 -> North | G13: =IFERROR(IF(E13=F13,"PASS","FAIL"),"FAIL") -> PASS
A14: 10 | B14: Single cell | C14: LastRevenue | D14: =LastRevenue | E14: =LastRevenue -> 1560 | F14: =Data!E21 -> 1560 | G14: =IFERROR(IF(E14=F14,"PASS","FAIL"),"FAIL") -> PASS
A15: 11 | B15: Range aggregate | C15: Units | D15: =SUM(Units) | E15: =SUM(Units) -> 1013 | F15: =SUM(Data!C2:C21) -> 1013 | G15: =IFERROR(IF(E15=F15,"PASS","FAIL"),"FAIL") -> PASS
A16: 12 | B16: Range aggregate | C16: Prices | D16: =AVERAGE(Prices) | E16: =AVERAGE(Prices) -> 17.9 | F16: =AVERAGE(Data!D2:D21) -> 17.9 | G16: =IFERROR(IF(E16=F16,"PASS","FAIL"),"FAIL") -> PASS
A17: 13 | B17: Range aggregate | C17: Revenue | D17: =MAX(Revenue) | E17: =MAX(Revenue) -> 2340 | F17: =MAX(Data!E2:E21) -> 2340 | G17: =IFERROR(IF(E17=F17,"PASS","FAIL"),"FAIL") -> PASS
A18: 14 | B18: Range aggregate | C18: Revenue | D18: =MIN(Revenue) | E18: =MIN(Revenue) -> 120 | F18: =MIN(Data!E2:E21) -> 120 | G18: =IFERROR(IF(E18=F18,"PASS","FAIL"),"FAIL") -> PASS
A19: 15 | B19: Range aggregate | C19: Units | D19: =COUNT(Units) | E19: =COUNT(Units) -> 20 | F19: =COUNT(Data!C2:C21) -> 20 | G19: =IFERROR(IF(E19=F19,"PASS","FAIL"),"FAIL") -> PASS
A20: 16 | B20: Range aggregate | C20: Regions | D20: =COUNTA(Regions) | E20: =COUNTA(Regions) -> 20 | F20: =COUNTA(Data!A2:A21) -> 20 | G20: =IFERROR(IF(E20=F20,"PASS","FAIL"),"FAIL") -> PASS
A21: 17 | B21: Range aggregate | C21: Units, Prices | D21: =SUMPRODUCT(Units,Prices) | E21: =SUMPRODUCT(Units,Prices) -> 17874 | F21: =SUMPRODUCT(Data!C2:C21,Data!D2:D21) -> 17874 | G21: =IFERROR(IF(E21=F21,"PASS","FAIL"),"FAIL") -> PASS
A22: 18 | B22: Array math | C22: Units, Prices | D22: =SUM(Units*Prices) | E22: {=SUM(Units*Prices)} -> 17874 | F22: =SUMPRODUCT(Data!C2:C21,Data!D2:D21) -> 17874 | G22: =IFERROR(IF(E22=F22,"PASS","FAIL"),"FAIL") -> PASS
A23: 19 | B23: Conditional | C23: Regions, Revenue | D23: =SUMIF(Regions,"North",Revenue) | E23: =SUMIF(Regions,"North",Revenue) -> 3861 | F23: =SUMIF(Data!A2:A21,"North",Data!E2:E21) -> 3861 | G23: =IFERROR(IF(E23=F23,"PASS","FAIL"),"FAIL") -> PASS
A24: 20 | B24: Conditional | C24: Products | D24: =COUNTIF(Products,"A") | E24: =COUNTIF(Products,"A") -> 7 | F24: =COUNTIF(Data!B2:B21,"A") -> 7 | G24: =IFERROR(IF(E24=F24,"PASS","FAIL"),"FAIL") -> PASS
A25: 21 | B25: Conditional | C25: Regions, Units | D25: =AVERAGEIF(Regions,"East",Units) | E25: =AVERAGEIF(Regions,"East",Units) -> 50 | F25: =AVERAGEIF(Data!A2:A21,"East",Data!C2:C21) -> 50 | G25: =IFERROR(IF(E25=F25,"PASS","FAIL"),"FAIL") -> PASS
A26: 22 | B26: Conditional | C26: Revenue, Regions, Products | D26: =SUMIFS(Revenue,Regions,"West",Products,"B") | E26: =SUMIFS(Revenue,Regions,"West",Products,"B") -> 3900 | F26: =SUMIFS(Data!E2:E21,Data!A2:A21,"West",Data!B2:B21,"B") -> 3900 | G26: =IFERROR(IF(E26=F26,"PASS","FAIL"),"FAIL") -> PASS
A27: 23 | B27: Conditional | C27: Units, Threshold | D27: =COUNTIFS(Units,">"&Threshold) | E27: =COUNTIFS(Units,">"&Threshold) -> 10 | F27: =COUNTIFS(Data!C2:C21,">"&Inputs!B8) -> 10 | G27: =IFERROR(IF(E27=F27,"PASS","FAIL"),"FAIL") -> PASS
A28: 24 | B28: Lookup | C28: CommissionTable | D28: =VLOOKUP("South",CommissionTable,2,FALSE) | E28: =VLOOKUP("South",CommissionTable,2,FALSE) -> 0.04 | F28: =VLOOKUP("South",Inputs!D2:E5,2,FALSE) -> 0.04 | G28: =IFERROR(IF(E28=F28,"PASS","FAIL"),"FAIL") -> PASS
A29: 25 | B29: Lookup | C29: CommRates, CommRegions | D29: =INDEX(CommRates,MATCH("East",CommRegions,0)) | E29: =INDEX(CommRates,MATCH("East",CommRegions,0)) -> 0.06 | F29: =INDEX(Inputs!E2:E5,MATCH("East",Inputs!D2:D5,0)) -> 0.06 | G29: =IFERROR(IF(E29=F29,"PASS","FAIL"),"FAIL") -> PASS
A30: 26 | B30: Lookup | C30: CommRegions, CommRates | D30: =XLOOKUP("West",CommRegions,CommRates) | E30: =_xlfn.XLOOKUP("West",CommRegions,CommRates) -> 0.03 | F30: =_xlfn.XLOOKUP("West",Inputs!D2:D5,Inputs!E2:E5) -> 0.03 | G30: =IFERROR(IF(E30=F30,"PASS","FAIL"),"FAIL") -> PASS
A31: 27 | B31: Lookup | C31: SalesTable | D31: =INDEX(SalesTable,5,2) | E31: =INDEX(SalesTable,5,2) -> B | F31: =INDEX(Data!A2:E21,5,2) -> B | G31: =IFERROR(IF(E31=F31,"PASS","FAIL"),"FAIL") -> PASS
A32: 28 | B32: Lookup | C32: SalesHeader | D32: =MATCH("Revenue",SalesHeader,0) | E32: =MATCH("Revenue",SalesHeader,0) -> 5 | F32: =MATCH("Revenue",Data!A1:E1,0) -> 5 | G32: =IFERROR(IF(E32=F32,"PASS","FAIL"),"FAIL") -> PASS
A33: 29 | B33: Range dimensions | C33: SalesTable | D33: =ROWS(SalesTable) | E33: =ROWS(SalesTable) -> 20 | F33: =ROWS(Data!A2:E21) -> 20 | G33: =IFERROR(IF(E33=F33,"PASS","FAIL"),"FAIL") -> PASS
A34: 30 | B34: Range dimensions | C34: SalesTable | D34: =COLUMNS(SalesTable) | E34: =COLUMNS(SalesTable) -> 5 | F34: =COLUMNS(Data!A2:E21) -> 5 | G34: =IFERROR(IF(E34=F34,"PASS","FAIL"),"FAIL") -> PASS
A35: 31 | B35: Partial range | C35: FirstFiveUnits | D35: =SUM(FirstFiveUnits) | E35: =SUM(FirstFiveUnits) -> 236 | F35: =SUM(Data!C2:C6) -> 236 | G35: =IFERROR(IF(E35=F35,"PASS","FAIL"),"FAIL") -> PASS
A36: 32 | B36: Partial range | C36: LastFiveUnits | D36: =SUM(LastFiveUnits) | E36: =SUM(LastFiveUnits) -> 263 | F36: =SUM(Data!C17:C21) -> 263 | G36: =IFERROR(IF(E36=F36,"PASS","FAIL"),"FAIL") -> PASS
A37: 33 | B37: 2D partial range | C37: TopLeftBlock | D37: =SUM(TopLeftBlock) | E37: =SUM(TopLeftBlock) -> 169 | F37: =SUM(Data!C2:D4) -> 169 | G37: =IFERROR(IF(E37=F37,"PASS","FAIL"),"FAIL") -> PASS
A38: 34 | B38: Whole column | C38: UnitsColumn | D38: =SUM(UnitsColumn) | E38: =SUM(UnitsColumn) -> 1013 | F38: =SUM(Data!C:C) -> 1013 | G38: =IFERROR(IF(E38=F38,"PASS","FAIL"),"FAIL") -> PASS
A39: 35 | B39: Whole row | C39: HeaderRow | D39: =COUNTA(HeaderRow) | E39: =COUNTA(HeaderRow) -> 6 | F39: =COUNTA(Data!1:1) -> 6 | G39: =IFERROR(IF(E39=F39,"PASS","FAIL"),"FAIL") -> PASS
A40: 36 | B40: Sheet with space | C40: Q1Values | D40: =SUM(Q1Values) | E40: =SUM(Q1Values) -> 4500 | F40: =SUM('Q1 Sales'!B2:B4) -> 4500 | G40: =IFERROR(IF(E40=F40,"PASS","FAIL"),"FAIL") -> PASS
...

Sheet Inputs
A1: Parameter | B1: Value | D1: Region | E1: Commission
A2: TaxRate | B2: 0.08 | D2: North | E2: 0.05
A3: DiscountRate | B3: 0.05 | D3: South | E3: 0.04
A4: FXRate | B4: 1.1 | D4: East | E4: 0.06
A5: StartDate | B5: =DATE(2026,1,1) -> 46023 | D5: West | E5: 0.03
A6: SalesTarget | B6: 5000
A7: CompanyName | B7: Acme Corp
A8: Threshold | B8: 50
A9: Multiplier | B9: 3
A10: BonusAmount | B10: 250

Sheet Data
A1: Region | B1: Product | C1: Units | D1: Price | E1: Revenue | G1: Empty (for COUNTBLANK)
A2: North | B2: A | C2: 12 | D2: 10 | E2: =C2*D2 -> 120
A3: South | B3: B | C3: 45 | D3: 15 | E3: =C3*D3 -> 675
A4: East | B4: C | C4: 67 | D4: 20 | E4: =C4*D4 -> 1340
A5: West | B5: A | C5: 23 | D5: 12 | E5: =C5*D5 -> 276
A6: North | B6: B | C6: 89 | D6: 18 | E6: =C6*D6 -> 1602
A7: South | B7: C | C7: 34 | D7: 25 | E7: =C7*D7 -> 850
A8: East | B8: A | C8: 56 | D8: 8 | E8: =C8*D8 -> 448
A9: West | B9: B | C9: 78 | D9: 30 | E9: =C9*D9 -> 2340
A10: North | B10: C | C10: 15 | D10: 22 | E10: =C10*D10 -> 330
A11: South | B11: A | C11: 92 | D11: 14 | E11: =C11*D11 -> 1288
A12: East | B12: B | C12: 41 | D12: 16 | E12: =C12*D12 -> 656
A13: West | B13: C | C13: 63 | D13: 11 | E13: =C13*D13 -> 693
... A21: West | B21: B | C21: 60 | D21: 26 | E21: =C21*D21 -> 1560

Sheet Q1 Sales
A1: Month | B1: Sales
A2: Jan | B2: 1200
A3: Feb | B3: 1500
A4: Mar | B4: 1800
A5: Total | B5: =SUM(B2:B4) -> 4500

Sheet Names
A1: Name | B1: Scope | C1: Refers To | D1: Type | E1: Visible
A2: _Helper | B2: Workbook | C2: =Inputs!$B$10 | D2: Name starting with _ | E2: TRUE
A3: AvgPrice | B3: Workbook | C3: =AVERAGE(Data!$D$2:$D$21) | D3: Formula | E3: TRUE
A4: BonusAmount | B4: Workbook | C4: =Inputs!$B$10 | D4: Single cell | E4: TRUE
A5: CommissionTable | B5: Workbook | C5: =Inputs!$D$2:$E$5 | D5: 2D range | E5: TRUE
A6: CommRates | B6: Workbook | C6: =Inputs!$E$2:$E$5 | D6: Column range | E6: TRUE
A7: CommRegions | B7: Workbook | C7: =Inputs!$D$2:$D$5 | D7: Column range | E7: TRUE
A8: CompanyName | B8: Workbook | C8: =Inputs!$B$7 | D8: Single cell (text) | E8: TRUE
A9: ConstGreeting | B9: Workbook | C9: ="Hello" | D9: Constant (text) | E9: TRUE
A10: ConstPi | B10: Workbook | C10: =3.14159 | D10: Constant (number) | E10: TRUE
A11: ConstVAT | B11: Workbook | C11: =0.2 | D11: Constant (number) | E11: TRUE
A12: DiscountRate | B12: Workbook | C12: =Inputs!$B$3 | D12: Single cell | E12: TRUE
A13: DoubleTarget | B13: Workbook | C13: =Inputs!$B$6*2 | D13: Formula | E13: TRUE
... A51: LocalBonus | B51: Tests | C51: =Inputs!$B$10 | D51: Sheet scope (Tests) | E51: TRUE
